<?xml version="1.0"?>
<!-- This URDF was automatically created by SolidWorks to URDF Exporter! Originally created by Stephen Brawner (brawner@gmail.com) 
     Commit Version: 1.6.0-4-g7f85cfe  Build Version: 1.6.7995.38578
     For more information, please see http://wiki.ros.org/sw_urdf_exporter -->
<!-- <robot
  name="modelo_robot"> -->
  <robot xmlns:xacro="http://www.ros.org/wiki/xacro" name="mobile_robot">
  <link
    name="base_link">
    <inertial>
      <origin
        xyz="0.0100845530400964 -7.87633978411792E-06 -0.00660483212224633"
        rpy="0 0 0" />
      <mass
        value="0.128593928056721" />
      <inertia
        ixx="5.21456588108558E-05"
        ixy="1.21307508603112E-18"
        ixz="2.93683176055069E-20"
        iyy="0.000179567040468821"
        iyz="1.809875899634E-14"
        izz="0.00022799348701614" />
    </inertial>
    <visual>
      <origin
        xyz="0 0 0"
        rpy="0 0 0" />
      <geometry>
        <mesh
          filename="package://modelo_robot/meshes/base_link.STL" />
      </geometry>
      <material
        name="">
        <color
          rgba="1 1 1 0.3" />
      </material>
    </visual>
    <collision>
      <origin
        xyz="0 0 0"
        rpy="0 0 0" />
      <geometry>
        <mesh
          filename="package://modelo_robot/meshes/base_link.STL" />
      </geometry>
    </collision>
  </link>
  <link
    name="Rueda_derecha_link">
    <inertial>
      <origin
        xyz="-8.9146E-10 -3.2512E-08 0.011873"
        rpy="0 0 0" />
      <mass
        value="0.021404" />
      <inertia
        ixx="8.6283E-06"
        ixy="6.4381E-11"
        ixz="-1.062E-13"
        iyy="8.6269E-06"
        iyz="9.8999E-12"
        izz="1.4515E-05" />
    </inertial>
    <visual>
      <origin
        xyz="0 0 0"
        rpy="0 0 0" />
      <geometry>
        <mesh
          filename="package://modelo_robot/meshes/Rueda_derecha_link.STL" />
      </geometry>
      <material
        name="">
        <color
          rgba="0.79216 0.81961 0.93333 1" />
      </material>
    </visual>
    <collision>
      <origin
        xyz="0 0 0"
        rpy="0 0 0" />
      <geometry>
        <mesh
          filename="package://modelo_robot/meshes/Rueda_derecha_link.STL" />
      </geometry>
    </collision>
  </link>
  <joint
    name="Rueda_derecha_joint"
    type="continuous">
    <origin
      xyz="-0.033259 -0.08025 -0.01375"
      rpy="1.5708 0.042481 -3.1416" />
    <parent
      link="base_link" />
    <child
      link="Rueda_derecha_link" />
    <axis
      xyz="0 0 1" />
    <limit
      effort="100"
      velocity="100" />
    <dynamics
      friction="0.1" />
  </joint>
  <link
    name="Rueda_izquierda_link">
    <inertial>
      <origin
        xyz="8.9146E-10 -3.2512E-08 -0.011873"
        rpy="0 0 0" />
      <mass
        value="0.021404" />
      <inertia
        ixx="8.6283E-06"
        ixy="-6.4381E-11"
        ixz="-1.062E-13"
        iyy="8.6269E-06"
        iyz="-9.8999E-12"
        izz="1.4515E-05" />
    </inertial>
    <visual>
      <origin
        xyz="0 0 0"
        rpy="0 0 0" />
      <geometry>
        <mesh
          filename="package://modelo_robot/meshes/Rueda_izquierda_link.STL" />
      </geometry>
      <material
        name="">
        <color
          rgba="0.79216 0.81961 0.93333 1" />
      </material>
    </visual>
    <collision>
      <origin
        xyz="0 0 0"
        rpy="0 0 0" />
      <geometry>
        <mesh
          filename="package://modelo_robot/meshes/Rueda_izquierda_link.STL" />
      </geometry>
    </collision>
  </link>
  <joint
    name="Rueda_izquierda_joint"
    type="continuous">
    <origin
      xyz="-0.033259 0.08025 -0.01375"
      rpy="-1.5708 0.042481 0" />
    <parent
      link="base_link" />
    <child
      link="Rueda_izquierda_link" />
    <axis
      xyz="0 0 1" />
    <limit
      effort="100"
      velocity="100" />
    <dynamics
      friction="0.1" />
  </joint>
  <link
    name="Base_castor_link">
    <inertial>
      <origin
        xyz="0.0076868 -0.00024426 0.013506"
        rpy="0 0 0" />
      <mass
        value="0.5" />
      <inertia
        ixx="1.2468E-06"
        ixy="9.7727E-10"
        ixz="-2.4805E-07"
        iyy="1.3131E-06"
        iyz="2.4557E-09"
        izz="1.6977E-06" />
    </inertial>
    <visual>
      <origin
        xyz="0 0 0"
        rpy="0 0 0" />
      <geometry>
        <mesh
          filename="package://modelo_robot/meshes/Base_castor_link.STL" />
      </geometry>
      <material
        name="">
        <color
          rgba="0.63922 0.66667 0.67843 1" />
      </material>
    </visual>
    <collision>
      <origin
        xyz="0 0 0"
        rpy="0 0 0" />
      <geometry>
        <mesh
          filename="package://modelo_robot/meshes/Base_castor_link.STL" />
      </geometry>
    </collision>
  </link>
  <joint
    name="Base_castor_joint"
    type="continuous">
    <origin
      xyz="0.072581 0 -0.0025"
      rpy="3.1416 0 0" />
    <parent
      link="base_link" />
    <child
      link="Base_castor_link" />
    <axis
      xyz="0 0 1" />
    <limit
      effort="100"
      velocity="100" />
    <dynamics
      friction="0.01" />
  </joint>
  <link
    name="Rueda_castor_link">
    <inertial>
      <origin
        xyz="1.9957E-11 -1.6982E-11 -2.7771E-09"
        rpy="0 0 0" />
      <mass
        value="0.0082874" />
      <inertia
        ixx="6.3929E-07"
        ixy="-1.6338E-11"
        ixz="-2.6719E-09"
        iyy="6.3928E-07"
        iyz="2.2736E-09"
        izz="1.0111E-06" />
    </inertial>
    <visual>
      <origin
        xyz="0 0 0"
        rpy="0 0 0" />
      <geometry>
        <mesh
          filename="package://modelo_robot/meshes/Rueda_castor_link.STL" />
      </geometry>
      <material
        name="">
        <color
          rgba="1 1 1 1" />
      </material>
    </visual>
    <collision>
      <origin
        xyz="0 0 0"
        rpy="0 0 0" />
      <geometry>
        <mesh
          filename="package://modelo_robot/meshes/Rueda_castor_link.STL" />
      </geometry>
    </collision>
  </link>
  <joint
    name="Rueda_castor_joint"
    type="continuous">
    <origin
      xyz="0.015014 -0.00014167 0.02296"
      rpy="1.5708 -0.70503 0" />
    <parent
      link="Base_castor_link" />
    <child
      link="Rueda_castor_link" />
    <axis
      xyz="0 0 1" />
    <limit
      effort="100"
      velocity="100" />
    <dynamics
      friction="0.01" />
  </joint>

  <link name="Lidar_link">
  <inertial>
    <origin xyz="0 0 0.0" rpy="0 0 0.0"/>
    <mass value="0.01"/>
    <inertia ixx="0.0001"  ixy="0"  ixz="0" iyy="0.0001" iyz="0" izz="0.0001" />
  </inertial>
  <visual>
    <origin xyz="0 0 0" rpy="0 0 0"/>
    <geometry>
       <cylinder radius="0.01" length="0.05"/>
    </geometry>
    <material
      name="">
      <color
        rgba="1 1 0 0.5" />
    </material>
  </visual>
  <collision>
    <origin xyz="0 0 0.0" rpy="0 0 0"/>
    <geometry>
       <cylinder radius="0.01" length="0.05"/>
    </geometry>
    <material
      name="">
      <color
        rgba="1 1 1 0.5" />
    </material>
  </collision>
  </link>

  <joint
    name="Lidar_joint"
    type="fixed">
    <origin
      xyz="0.0 0 0.02"
      rpy="0 -0.087 0" />
    <parent
      link="base_link" />
    <child
      link="Lidar_link" />
    <axis
      xyz="1 0 0" />
  </joint>

  <link name="imu_link"/>
  <joint
    name="imu_joint"
    type="fixed">
    <origin
      xyz="0.0 0 0.0"
      rpy="0 0 0" />
    <parent
      link="base_link" />
    <child
      link="imu_link" />
    <axis
      xyz="1 0 0" />
  </joint>


  <!--LIDAR CONFIGURATION-->

  <gazebo reference="Lidar_link">
    <sensor name="lidar" type="ray">
      <always_on>true</always_on>
      <visualize>true</visualize>
      <update_rate>20</update_rate>
      <ray>
        <scan>
          <horizontal>
            <samples>120</samples>
            <resolution>1.000000</resolution>
            <min_angle>-1.57079</min_angle>
            <max_angle>1.57079</max_angle>
          </horizontal>
        </scan>
        <range>
          <min>0.07</min>
          <max>5.0</max>
          <resolution>0.015</resolution>
        </range>
        <noise>
          <type>gaussian</type>
          <mean>0.0</mean>
          <stddev>0.01</stddev>
        </noise>
      </ray>
      <plugin name="scan" filename="libgazebo_ros_ray_sensor.so">
        <ros>
          <remapping>~/out:=laser_scan</remapping>
        </ros>
        <output_type>sensor_msgs/LaserScan</output_type>
        <frame_name>Lidar_link</frame_name>
      </plugin>
    </sensor>
  </gazebo>

  <gazebo reference="Lidar_link">
    <mu1>0.1</mu1>
    <mu2>0.1</mu2>
    <kp>1000000</kp>
    <kd>1</kd>
    <material>Gazebo/Yellow</material>
  </gazebo>

    <!--IMU sensor-->

  <gazebo reference="imu_link">
    <gravity>true</gravity>
    <sensor name="imu_sensor" type="imu">
      <always_on>true</always_on>
      <update_rate>100</update_rate>
      <visualize>true</visualize>
      <topic>imu_data</topic>
      <plugin filename="libgazebo_ros_imu_sensor.so" name="imu_plugin">
        <topicName>imu_data</topicName>
        <bodyName>imu_link</bodyName>
        <updateRateHZ>10.0</updateRateHZ>
        <gaussianNoise>0.005</gaussianNoise>
        <xyzOffset>0 0 0</xyzOffset>
        <rpyOffset>0 0 0</rpyOffset>
        <frameName>imu_link</frameName>
        <initialOrientationAsReference>true</initialOrientationAsReference>
      </plugin>
      <pose>0 0 0 0 0 0</pose>
    </sensor>
  </gazebo>


<!-- PLUGINS THE GAZEBO -->
  <gazebo>
    <plugin name="two_wheeled_robot_diff_drive" filename="libgazebo_ros_diff_drive.so">
 
      <update_rate>100</update_rate>
      
      <!-- wheels -->
      <left_joint>Rueda_izquierda_joint</left_joint>
      <right_joint>Rueda_derecha_joint</right_joint>
 
      <!-- kinematics -->
      <wheel_separation>0.15</wheel_separation>
      <wheel_diameter>0.06</wheel_diameter>
 
      <!-- limits -->
      <max_wheel_torque>20</max_wheel_torque>
      <max_wheel_acceleration>20.0</max_wheel_acceleration>
 
      <!-- Receive velocity commands on this ROS topic -->
      <command_topic>cmd_vel</command_topic>
 
      <!-- output -->
      <!-- When false, publish no wheel odometry data to a ROS topic -->
      <publish_odom>true</publish_odom>
 
      <!-- When true, publish coordinate transform from odom to base_footprint -->
      <!-- I usually use the robot_localization package to publish this transform -->  
      <publish_odom_tf>true</publish_odom_tf>
     
      <!-- When true, publish coordinate transform from base_link to the wheels -->
      <!-- The robot_state_publisher package is often used to publish this transform -->  
      <publish_wheel_tf>true</publish_wheel_tf>
 
      <odometry_topic>odom</odometry_topic>
      <odometry_frame>odom_link</odometry_frame>
      <robot_base_frame>base_link</robot_base_frame>
 
      <odometry_source>1</odometry_source>
      <ros>
        <remapping>odom:=wheel/odometry</remapping>
      </ros>
    </plugin>
  </gazebo>

  <gazebo>
    <plugin name="gazebo_ros_joint_state_publisher"
        filename="libgazebo_ros_joint_state_publisher.so">
        <update_rate>100</update_rate>
        <joint_name>Base_castor_joint</joint_name>
        <joint_name>Rueda_castor_joint</joint_name>
    </plugin>
  </gazebo>


</robot>