<?xml version="1.0" encoding="utf-8"?>
<!-- This URDF was automatically created by SolidWorks to URDF Exporter! Originally created by Stephen Brawner (brawner@gmail.com) 
     Commit Version: 1.6.0-4-g7f85cfe  Build Version: 1.6.7995.38578
     For more information, please see http://wiki.ros.org/sw_urdf_exporter -->
<robot
  name="sentinel">
  <link
    name="base_link">
    <inertial>
      <origin
        xyz="-0.00105760737631283 -2.19032190874277E-05 0.0255202576150771"
        rpy="0 0 0" />
      <mass
        value="0.316163168273078" />
      <inertia
        ixx="0.000625135781292764"
        ixy="-2.93764633305647E-06"
        ixz="1.91503476533365E-06"
        iyy="0.000872141508316583"
        iyz="3.17766970761198E-07"
        izz="0.00105492627973741" />
    </inertial>
    <visual>
      <origin
        xyz="0 0 0"
        rpy="0 0 0" />
      <geometry>
        <mesh
          filename="package://sentinel/meshes/base_link.STL" />
      </geometry>
      <material
        name="">
        <color
          rgba="1 0.937254901960784 0.137254901960784 1" />
      </material>
    </visual>
    <collision>
      <origin
        xyz="0 0 0"
        rpy="0 0 0" />
      <geometry>
        <mesh
          filename="package://sentinel/meshes/base_link.STL" />
      </geometry>
    </collision>
  </link>
  <link
    name="Left_wheel_link">
    <inertial>
      <origin
        xyz="-4.1176E-10 3.0207E-11 0.0042086"
        rpy="0 0 0" />
      <mass
        value="0.023896" />
      <inertia
        ixx="7.625E-06"
        ixy="-4.7831E-15"
        ixz="-5.6353E-15"
        iyy="7.6248E-06"
        iyz="-4.5111E-16"
        izz="1.4592E-05" />
    </inertial>
    <visual>
      <origin
        xyz="0 0 0"
        rpy="0 0 0" />
      <geometry>
        <mesh
          filename="package://sentinel/meshes/Left_wheel_link.STL" />
      </geometry>
      <material
        name="">
        <color
          rgba="1 1 1 1" />
      </material>
    </visual>
    <collision>
      <origin
        xyz="0 0 0"
        rpy="0 0 0" />
      <geometry>
        <mesh
          filename="package://sentinel/meshes/Left_wheel_link.STL" />
      </geometry>
    </collision>
  </link>
  <joint
    name="Left_wheel_joint"
    type="continuous">
    <origin
      xyz="-0.00023583 0.052 -0.012"
      rpy="-1.5708 -0.71575 0" />
    <parent
      link="base_link" />
    <child
      link="Left_wheel_link" />
    <axis
      xyz="0 0 1" />
    <limit
      effort="100"
      velocity="100" />
    <dynamics
      friction="0.1" />
  </joint>
  <link
    name="Right_wheel_link">
    <inertial>
      <origin
        xyz="4.1176E-10 3.0207E-11 -0.011709"
        rpy="0 0 0" />
      <mass
        value="0.023896" />
      <inertia
        ixx="7.625E-06"
        ixy="4.7831E-15"
        ixz="-5.6353E-15"
        iyy="7.6248E-06"
        iyz="4.5111E-16"
        izz="1.4592E-05" />
    </inertial>
    <visual>
      <origin
        xyz="0 0 0"
        rpy="0 0 0" />
      <geometry>
        <mesh
          filename="package://sentinel/meshes/Right_wheel_link.STL" />
      </geometry>
      <material
        name="">
        <color
          rgba="1 1 1 1" />
      </material>
    </visual>
    <collision>
      <origin
        xyz="0 0 0"
        rpy="0 0 0" />
      <geometry>
        <mesh
          filename="package://sentinel/meshes/Right_wheel_link.STL" />
      </geometry>
    </collision>
  </link>
  <joint
    name="Right_wheel_joint"
    type="continuous">
    <origin
      xyz="-0.00023583 -0.0445 -0.012"
      rpy="-1.5708 -0.91629 0" />
    <parent
      link="base_link" />
    <child
      link="Right_wheel_link" />
    <axis
      xyz="0 0 1" />
    <limit
      effort="100"
      velocity="100" />
    <dynamics
      friction="0.1" />
  </joint>
  <link
    name="Deep_camera_link">
    <inertial>
      <origin
        xyz="-0.0042251 0.0032378 -0.0020974"
        rpy="0 0 0" />
      <mass
        value="0.048201" />
      <inertia
        ixx="2.7391E-05"
        ixy="-4.2599E-07"
        ixz="7.5493E-09"
        iyy="3.3506E-06"
        iyz="2.1161E-09"
        izz="2.6652E-05" />
    </inertial>
    <visual>
      <origin
        xyz="0 0 0"
        rpy="0 0 0" />
      <geometry>
        <mesh
          filename="package://sentinel/meshes/Deep_camera_link.STL" />
      </geometry>
      <material
        name="">
        <color
          rgba="0.77647 0.75686 0.73725 1" />
      </material>
    </visual>
    <collision>
      <origin
        xyz="0 0 0"
        rpy="0 0 0" />
      <geometry>
        <mesh
          filename="package://sentinel/meshes/Deep_camera_link.STL" />
      </geometry>
    </collision>
  </link>
  <joint
    name="Deep_camera_joint"
    type="fixed">
    <origin
      xyz="0.067909 -0.0033318 0.047549"
      rpy="0 0 0" />
    <parent
      link="base_link" />
    <child
      link="Deep_camera_link" />
    <axis
      xyz="0 0 0" />
    <limit
      lower="0"
      upper="0"
      effort="0"
      velocity="0" />
  </joint>
  <link
    name="Lidar_link">
    <inertial>
      <origin
        xyz="-0.0067683 9.1777E-05 -0.0073879"
        rpy="0 0 0" />
      <mass
        value="1.3304" />
      <inertia
        ixx="0.00061474"
        ixy="-8.0027E-07"
        ixz="-0.00015819"
        iyy="0.0009605"
        iyz="3.096E-06"
        izz="0.0010981" />
    </inertial>
    <visual>
      <origin
        xyz="0 0 0"
        rpy="0 0 0" />
      <geometry>
        <mesh
          filename="package://sentinel/meshes/Lidar_link.STL" />
      </geometry>
      <material
        name="">
        <color
          rgba="0.29804 0.29804 0.29804 1" />
      </material>
    </visual>
    <collision>
      <origin
        xyz="0 0 0"
        rpy="0 0 0" />
      <geometry>
        <mesh
          filename="package://sentinel/meshes/Lidar_link.STL" />
      </geometry>
    </collision>
  </link>
  <joint
    name="Lidar_joint"
    type="fixed">
    <origin
      xyz="-0.00023583 0 0.13965"
      rpy="0 0 0" />
    <parent
      link="base_link" />
    <child
      link="Lidar_link" />
    <axis
      xyz="0 0 0" />
  </joint>
  <link
    name="Front_wheel_Link">
    <inertial>
      <origin
        xyz="6.9389E-18 0 -6.997E-18"
        rpy="0 0 0" />
      <mass
        value="0.0027985" />
      <inertia
        ixx="1.0504E-07"
        ixy="5.2972E-40"
        ixz="-3.709E-24"
        iyy="1.0504E-07"
        iyz="4.6008E-24"
        izz="6.747E-08" />
    </inertial>
    <visual>
      <origin
        xyz="0 0 0"
        rpy="0 0 0" />
      <geometry>
        <mesh
          filename="package://sentinel/meshes/Front_wheel_Link.STL" />
      </geometry>
      <material
        name="">
        <color
          rgba="0.75294 0.75294 0.75294 1" />
      </material>
    </visual>
    <collision>
      <origin
        xyz="0 0 0"
        rpy="0 0 0" />
      <geometry>
        <mesh
          filename="package://sentinel/meshes/Front_wheel_Link.STL" />
      </geometry>
    </collision>
  </link>
  <joint
    name="Front_wheel_Joint"
    type="continuous">
    <origin
      xyz="0.034514 0 -0.0359"
      rpy="-1.5708 0 0" />
    <parent
      link="base_link" />
    <child
      link="Front_wheel_Link" />
    <axis
      xyz="0 0 1" />
    <limit
      effort="100"
      velocity="100" />
    <dynamics
      friction="0.1" />
  </joint>
  <link
    name="Rear_wheel_Link">
    <inertial>
      <origin
        xyz="-6.9389E-18 2.0817E-17 6.2414E-18"
        rpy="0 0 0" />
      <mass
        value="0.0027985" />
      <inertia
        ixx="1.0504E-07"
        ixy="0"
        ixz="5.8782E-25"
        iyy="1.0504E-07"
        iyz="-4.9349E-24"
        izz="6.747E-08" />
    </inertial>
    <visual>
      <origin
        xyz="0 0 0"
        rpy="0 0 0" />
      <geometry>
        <mesh
          filename="package://sentinel/meshes/Rear_wheel_Link.STL" />
      </geometry>
      <material
        name="">
        <color
          rgba="0.75294 0.75294 0.75294 1" />
      </material>
    </visual>
    <collision>
      <origin
        xyz="0 0 0"
        rpy="0 0 0" />
      <geometry>
        <mesh
          filename="package://sentinel/meshes/Rear_wheel_Link.STL" />
      </geometry>
    </collision>
  </link>
  <joint
    name="Rear_wheel_Joint"
    type="continuous">
    <origin
      xyz="-0.060236 0 -0.0359"
      rpy="1.5708 0 0" />
    <parent
      link="base_link" />
    <child
      link="Rear_wheel_Link" />
    <axis
      xyz="0 0 1" />
    <limit
      effort="100"
      velocity="100" />
    <dynamics
      friction="0.1" />
  </joint>
</robot>